Workbook
Name dias_op: Supuestos!$C$5
Name dias_peak: Supuestos!$C$6
Name f_dem: Supuestos!$C$7
Name f_perd: Supuestos!$C$8
Name sem_mes: Supuestos!$C$9
Name sem_anio: Supuestos!$C$10
Name ticket: Supuestos!$C$11
Name margen: Supuestos!$C$12
Name adopcion: Supuestos!$C$13
Name noshow_con: Supuestos!$C$14
Name noshow_sin: Supuestos!$C$15
Name mix_debito: Supuestos!$C$16
Name horas: Supuestos!$C$17
Name valor_hora: Supuestos!$C$18
Name abono: Supuestos!$C$19
Name uf: Supuestos!$C$20
Name usd: Supuestos!$C$21
Name utm: Supuestos!$C$22
Name dominio: Supuestos!$C$23
Name wp_deb: Supuestos!$C$24
Name wp_cre: Supuestos!$C$25
Name wp_min_deb: Supuestos!$C$26
Name wp_min_cre: Supuestos!$C$27
Name mp_pct: Supuestos!$C$28
Name iva: Supuestos!$C$29
Name opex: Supuestos!$C$30
Name com_mix: Abono_ROI!$B$6
Name inversion: Abono_ROI!$B$8

Sheet Supuestos
A1: Proyecto Barbería Big-Boys — Supuestos y parámetros (celdas amarillas editables)
A2: Consulta de valores externos: 09-10-2026. Todo supuesto está marcado para validación.
A4: ID | B4: Parámetro | C4: Valor | D4: Fuente / estado
A5: S-02 | B5: Días de operación por semana | C5: 6 | D5: Supuesto — por validar
A6: S-03 | B6: Días peak por semana (viernes y sábado) | C6: 2 | D6: Supuesto — por validar
A7: S-04 | B7: Factor de demanda día normal / peak | C7: 0.6 | D7: Supuesto — por validar
A8: S-05 | B8: Factor de abandono día normal / peak | C8: 0.3 | D8: Supuesto — por validar
A9: S-06 | B9: Semanas por mes | C9: =52/12 | D9: 52/12
A10: S-06 | B10: Semanas por año | C10: 52 | D10: Sin descontar feriados
A11: S-07 | B11: Precio del corte (valor oficial de la pérdida) | C11: 11900 | D11: Precio real del negocio
A12: S-08 | B12: Margen de contribución | C12: 0.5 | D12: Supuesto — por validar
A13: S-09 | B13: Adopción de reserva online | C13: 0.3 | D13: Supuesto — por validar
A14: S-10 | B14: No-show con abono (incluye anulación < 24 h) | C14: 0.05 | D14: Supuesto — por validar
A15: S-10 | B15: No-show referencial sin abono | C15: 0.15 | D15: Supuesto — por validar
A16: S-11 | B16: % abonos con débito/prepago | C16: 0.6 | D16: Supuesto — por validar
A17: S-12 | B17: Horas del equipo | C17: 312 | D17: EDT (documento 06)
A18: S-12 | B18: Valor hora (CLP) | C18: 6111 | D18: Sueldo junior $1.100.000 / 180 h
A19: — | B19: Abono de reserva (CLP) | C19: 3000 | D19: Definido por el negocio
A20: — | B20: UF (06-10-2026) | C20: 41106.35 | D20: Pauta.cl
A21: — | B21: Dólar observado (01-10-2026) | C21: 972.6 | D21: SII
... A29: — | B29: IVA | C29: 0.19 | D29: Ley IVA
A30: — | B30: Costo operativo anual (VPS + dominio) | C30: =19900*12+dominio | D30: V2Networks Cloud-1 (IVA incl.)

Sheet KPIs
A1: KPIs por sucursal — situación actual y proyección (día peak + días normales)
A3: Sucursal | B3: Atendidos/día peak | C3: Se van/día peak | D3: Demanda | E3: Tasa de atención | F3: % pérdida | G3: Perdidos/semana | H3: Perdidos/mes | I3: Perdidos/año | J3: Ingreso perdido/mes | K3: Ingreso perdido/año | L3: Recuperados/año 30% | M3: Pérdida evitada 30% | N3: Recuperados/año 50% | O3: Pérdida evitada 50% | P3: Recuperados/año 70% | Q3: Pérdida evitada 70%
A4: Peñaflor – Sucursal 21 de Mayo | B4: 70 | C4: 12 | D4: =B4+C4 | E4: =B4/D4 | F4: =C4/D4 | G4: =C4*dias_peak+C4*f_perd*(dias_op-dias_peak) | H4: =G4*sem_mes | I4: =G4*sem_anio | J4: =H4*ticket | K4: =I4*ticket | L4: =I4*0.3 | M4: =I4*0.3*ticket | N4: =I4*0.5 | O4: =I4*0.5*ticket | P4: =I4*0.7 | Q4: =I4*0.7*ticket
A5: Peñaflor – Sucursal Alcalde Luis Araya Cereceda | B5: 30 | C5: 7 | D5: =B5+C5 | E5: =B5/D5 | F5: =C5/D5 | G5: =C5*dias_peak+C5*f_perd*(dias_op-dias_peak) | H5: =G5*sem_mes | I5: =G5*sem_anio | J5: =H5*ticket | K5: =I5*ticket | L5: =I5*0.3 | M5: =I5*0.3*ticket | N5: =I5*0.5 | O5: =I5*0.5*ticket | P5: =I5*0.7 | Q5: =I5*0.7*ticket
A6: Subtotal Peñaflor | B6: =B4+B5 | C6: =C4+C5 | D6: =B6+C6 | E6: =B6/D6 | F6: =C6/D6 | G6: =C6*dias_peak+C6*f_perd*(dias_op-dias_peak) | H6: =G6*sem_mes | I6: =G6*sem_anio | J6: =H6*ticket | K6: =I6*ticket | L6: =I6*0.3 | M6: =I6*0.3*ticket | N6: =I6*0.5 | O6: =I6*0.5*ticket | P6: =I6*0.7 | Q6: =I6*0.7*ticket
A7: Talagante | B7: 30 | C7: 7 | D7: =B7+C7 | E7: =B7/D7 | F7: =C7/D7 | G7: =C7*dias_peak+C7*f_perd*(dias_op-dias_peak) | H7: =G7*sem_mes | I7: =G7*sem_anio | J7: =H7*ticket | K7: =I7*ticket | L7: =I7*0.3 | M7: =I7*0.3*ticket | N7: =I7*0.5 | O7: =I7*0.5*ticket | P7: =I7*0.7 | Q7: =I7*0.7*ticket
A8: Total consolidado | B8: =B4+B5+B7 | C8: =C4+C5+C7 | D8: =B8+C8 | E8: =B8/D8 | F8: =C8/D8 | G8: =C8*dias_peak+C8*f_perd*(dias_op-dias_peak) | H8: =G8*sem_mes | I8: =G8*sem_anio | J8: =H8*ticket | K8: =I8*ticket | L8: =I8*0.3 | M8: =I8*0.3*ticket | N8: =I8*0.5 | O8: =I8*0.5*ticket | P8: =I8*0.7 | Q8: =I8*0.7*ticket
A11: Fórmulas: perdidos/semana = se van × días peak + se van × factor abandono × días normales; perdidos/mes = semana × 52/12; año = semana × 52; ingreso perdido = perdidos × ticket.
A12: Atendidos/semana (consolidado): | B12: =B8*dias_peak+B8*f_dem*(dias_op-dias_peak)
A13: Atendidos/año (consolidado): | B13: =B12*sem_anio

Sheet Abono_ROI
A1: Abono de reserva, comisiones y ROI
A3: Concepto | B3: Valor
A4: Comisión Webpay débito por abono (con IVA) | B4: =MAX(abono*wp_deb,wp_min_deb*uf)*(1+iva)
A5: Comisión Webpay crédito por abono (con IVA) | B5: =MAX(abono*wp_cre,wp_min_cre*uf)*(1+iva)
A6: Comisión mezcla débito/crédito | B6: =B4*mix_debito+B5*(1-mix_debito)
A7: Comisión Mercado Pago por abono (con IVA) | B7: =abono*mp_pct*(1+iva)
A8: Inversión valorizada (horas + dominio) | B8: =horas*valor_hora+dominio
A10: Concepto | B10: Conservador (30%) | C10: Medio (50%) | D10: Optimista (70%)
A11: % recuperación | B11: 0.3 | C11: 0.5 | D11: 0.7
A12: Clientes recuperados/año | B12: =KPIs!$I$8*B11 | C12: =KPIs!$I$8*C11 | D12: =KPIs!$I$8*D11
A13: Ingreso adicional bruto/año | B13: =B12*ticket | C13: =C12*ticket | D13: =D12*ticket
A14: Margen de contribución | B14: =B13*margen | C14: =C13*margen | D14: =D13*margen
A15: Reservas con abono/año | B15: =adopcion*KPIs!$B$13+B12 | C15: =adopcion*KPIs!$B$13+C12 | D15: =adopcion*KPIs!$B$13+D12
A16: Abonos retenidos (ingreso) | B16: =B15*noshow_con*abono | C16: =C15*noshow_con*abono | D16: =D15*noshow_con*abono
A17: Comisiones de pasarela | B17: =B15*com_mix | C17: =C15*com_mix | D17: =D15*com_mix
A18: Costo operativo anual | B18: =opex | C18: =opex | D18: =opex
A19: Beneficio neto anual | B19: =B14+B16-B17-B18 | C19: =C14+C16-C17-C18 | D19: =D14+D16-D17-D18
A20: ROI primer año | B20: =(B19-inversion)/inversion | C20: =(C19-inversion)/inversion | D20: =(D19-inversion)/inversion
A21: Período de recuperación (meses) | B21: =inversion/(B19/12) | C21: =inversion/(C19/12) | D21: =inversion/(D19/12)

Sheet Sensibilidad
A1: Sensibilidad del precio de referencia (consolidado; ROI escenario medio 50%)
A3: Precio de referencia | B3: Precio | C3: Pérdida/año | D3: Ganancia adicional/año (50%) | E3: Beneficio neto (50%) | F3: ROI (50%) | G3: Recuperación (meses)
A4: Barba (mínimo) | B4: 8330 | C4: =KPIs!$I$8*B4 | D4: =KPIs!$I$8*0.5*B4 | E4: =D4*margen+Abono_ROI!$C$16-Abono_ROI!$C$17-Abono_ROI!$C$18 | F4: =(E4-inversion)/inversion | G4: =inversion/(E4/12)
A5: Corte (oficial) | B5: 11900 | C5: =KPIs!$I$8*B5 | D5: =KPIs!$I$8*0.5*B5 | E5: =D5*margen+Abono_ROI!$C$16-Abono_ROI!$C$17-Abono_ROI!$C$18 | F5: =(E5-inversion)/inversion | G5: =inversion/(E5/12)
A6: Corte + Cejas | B6: 15470 | C6: =KPIs!$I$8*B6 | D6: =KPIs!$I$8*0.5*B6 | E6: =D6*margen+Abono_ROI!$C$16-Abono_ROI!$C$17-Abono_ROI!$C$18 | F6: =(E6-inversion)/inversion | G6: =inversion/(E6/12)
A7: Corte + Cejas + Lavado | B7: 17850 | C7: =KPIs!$I$8*B7 | D7: =KPIs!$I$8*0.5*B7 | E7: =D7*margen+Abono_ROI!$C$16-Abono_ROI!$C$17-Abono_ROI!$C$18 | F7: =(E7-inversion)/inversion | G7: =inversion/(E7/12)
A8: Corte + Barba | B8: 20230 | C8: =KPIs!$I$8*B8 | D8: =KPIs!$I$8*0.5*B8 | E8: =D8*margen+Abono_ROI!$C$16-Abono_ROI!$C$17-Abono_ROI!$C$18 | F8: =(E8-inversion)/inversion | G8: =inversion/(E8/12)
A9: S. Completo (máximo) | B9: 23800 | C9: =KPIs!$I$8*B9 | D9: =KPIs!$I$8*0.5*B9 | E9: =D9*margen+Abono_ROI!$C$16-Abono_ROI!$C$17-Abono_ROI!$C$18 | F9: =(E9-inversion)/inversion | G9: =inversion/(E9/12)

Sheet Servicios
A1: Servicio | B1: Precio | C1: Categoría | D1: Duración (min) | E1: Agendable en línea
A2: Corte | B2: 11900 | C2: CORTE | D2: 40 | E2: Sí
A3: Corte + Cejas | B3: 15470 | C3: COMBO | D3: 45 | E3: Sí
A4: Corte + Barba | B4: 20230 | C4: COMBO | D4: 50 | E4: Sí
A5: S. Completo | B5: 23800 | C5: COMBO | D5: 60 | E5: Sí
A6: Corte + Cejas + Lavado | B6: 17850 | C6: COMBO | D6: 55 | E6: Sí
A7: Lavado | B7: 3570 | C7: COMPLEMENTO | D7: 15 | E7: No
A8: Barba | B8: 8330 | C8: BARBA | D8: 30 | E8: Sí
A9: Cejas | B9: 3570 | C9: COMPLEMENTO | D9: 15 | E9: No
A10: Mascarillas Faciales | B10: 2380 | C10: COMPLEMENTO | D10: 15 | E10: No

Sheet Ley_21719
A1: Riesgo de sanciones evitado (Ley N° 21.719, art. 35)
A3: Infracción | B3: UTM | C3: CLP
A4: Leve | B4: 5000 | C4: =B4*utm
A5: Grave | B5: 10000 | C5: =B5*utm
A6: Gravísima | B6: 20000 | C6: =B6*utm

Sheet Costos_Cloud
A1: Estimación de costos cloud (escenario futuro) — precios consultados el 09-10-2026
A3: Proveedor | B3: Escenario | C3: Componente | D3: USD/mes | E3: CLP/mes
A4: AWS (sa-east-1 São Paulo) | B4: Bajo | C4: Cómputo EC2 t4g.small (2 vCPU, 2 GiB) | D4: 19.564 | E4: =D4*usd
A5: AWS (sa-east-1 São Paulo) | B5: Bajo | C5: BD RDS PostgreSQL db.t4g.micro Single-AZ | D5: 24.82 | E5: =D5*usd
A6: AWS (sa-east-1 São Paulo) | B6: Bajo | C6: Almacenamiento BD gp3 20 GB | D6: 4.38 | E6: =D6*usd
A7: AWS (sa-east-1 São Paulo) | B7: Bajo | C7: Respaldos (incluidos hasta tamaño BD) + S3 10 GB | D7: 0.405 | E7: =D7*usd
A8: AWS (sa-east-1 São Paulo) | B8: Bajo | C8: Correo Amazon SES (3.000/mes) | D8: 0.3 | E8: =D8*usd
A9: AWS (sa-east-1 São Paulo) | B9: Bajo | C9: Soporte (Basic) | D9: 0 | E9: =D9*usd
A10: AWS (sa-east-1 São Paulo) | B10: Bajo | C10: Total mensual (incluye dominio prorrateado) | D10: =SUM(D4:D9) | E10: =SUM(E4:E9)+dominio/12
A11: AWS (sa-east-1 São Paulo) | B11: Medio | C11: Cómputo EC2 t4g.medium (2 vCPU, 4 GiB) | D11: 39.128 | E11: =D11*usd
A12: AWS (sa-east-1 São Paulo) | B12: Medio | C12: BD RDS PostgreSQL db.t4g.small Multi-AZ | D12: 100.01 | E12: =D12*usd
A13: AWS (sa-east-1 São Paulo) | B13: Medio | C13: Almacenamiento BD gp3 50 GB Multi-AZ | D13: 21.9 | E13: =D13*usd
A14: AWS (sa-east-1 São Paulo) | B14: Medio | C14: Respaldos + S3 50 GB | D14: 2.025 | E14: =D14*usd
A15: AWS (sa-east-1 São Paulo) | B15: Medio | C15: Correo Amazon SES (20.000/mes) | D15: 2 | E15: =D15*usd
A16: AWS (sa-east-1 São Paulo) | B16: Medio | C16: Soporte Business Support+ (mínimo) | D16: 29 | E16: =D16*usd
A17: AWS (sa-east-1 São Paulo) | B17: Medio | C17: Total mensual (incluye dominio prorrateado) | D17: =SUM(D11:D16) | E17: =SUM(E11:E16)+dominio/12
A18: AWS (sa-east-1 São Paulo) | B18: Alto | C18: Cómputo 2× EC2 t4g.medium | D18: 78.256 | E18: =D18*usd
A19: AWS (sa-east-1 São Paulo) | B19: Alto | C19: BD RDS PostgreSQL db.t4g.medium Multi-AZ | D19: 200.75 | E19: =D19*usd
A20: AWS (sa-east-1 São Paulo) | B20: Alto | C20: Almacenamiento BD gp3 100 GB Multi-AZ | D20: 43.8 | E20: =D20*usd
A21: AWS (sa-east-1 São Paulo) | B21: Alto | C21: Respaldos + S3 200 GB | D21: 8.1 | E21: =D21*usd
A22: AWS (sa-east-1 São Paulo) | B22: Alto | C22: Correo Amazon SES (60.000/mes) | D22: 6 | E22: =D22*usd
A23: AWS (sa-east-1 São Paulo) | B23: Alto | C23: Soporte Business Support+ (mínimo) | D23: 29 | E23: =D23*usd
A24: AWS (sa-east-1 São Paulo) | B24: Alto | C24: Total mensual (incluye dominio prorrateado) | D24: =SUM(D18:D23) | E24: =SUM(E18:E23)+dominio/12
A25: Microsoft Azure (Chile Central, Santiago) | B25: Bajo | C25: Cómputo VM B2ats v2 (2 vCPU, 1 GiB) | D25: 9.636 | E25: =D25*usd
A26: Microsoft Azure (Chile Central, Santiago) | B26: Bajo | C26: BD PostgreSQL Flexible B1ms | D26: 17.374 | E26: =D26*usd
A27: Microsoft Azure (Chile Central, Santiago) | B27: Bajo | C27: Almacenamiento BD 32 GB | D27: 5.152 | E27: =D27*usd
A28: Microsoft Azure (Chile Central, Santiago) | B28: Bajo | C28: Respaldos (gratis hasta 100% del almacenamiento) + Blob 10 GB | D28: 0.2576 | E28: =D28*usd
A29: Microsoft Azure (Chile Central, Santiago) | B29: Bajo | C29: Correo transaccional (Amazon SES, 3.000/mes) | D29: 0.3 | E29: =D29*usd
A30: Microsoft Azure (Chile Central, Santiago) | B30: Bajo | C30: Soporte (Basic) | D30: 0 | E30: =D30*usd
A31: Microsoft Azure (Chile Central, Santiago) | B31: Bajo | C31: Total mensual (incluye dominio prorrateado) | D31: =SUM(D25:D30) | E31: =SUM(E25:E30)+dominio/12
A32: Microsoft Azure (Chile Central, Santiago) | B32: Medio | C32: Cómputo VM B2s (2 vCPU, 4 GiB) | D32: 42.486 | E32: =D32*usd
A33: Microsoft Azure (Chile Central, Santiago) | B33: Medio | C33: BD PostgreSQL Flexible B2s con alta disponibilidad | D33: 138.992 | E33: =D33*usd
A34: Microsoft Azure (Chile Central, Santiago) | B34: Medio | C34: Almacenamiento BD 64 GB (HA) | D34: 20.608 | E34: =D34*usd
A35: Microsoft Azure (Chile Central, Santiago) | B35: Medio | C35: Respaldos + Blob 50 GB | D35: 1.288 | E35: =D35*usd
A36: Microsoft Azure (Chile Central, Santiago) | B36: Medio | C36: Correo transaccional (20.000/mes) | D36: 2 | E36: =D36*usd
A37: Microsoft Azure (Chile Central, Santiago) | B37: Medio | C37: Soporte Developer | D37: 29 | E37: =D37*usd
A38: Microsoft Azure (Chile Central, Santiago) | B38: Medio | C38: Total mensual (incluye dominio prorrateado) | D38: =SUM(D32:D37) | E38: =SUM(E32:E37)+dominio/12
A39: Microsoft Azure (Chile Central, Santiago) | B39: Alto | C39: Cómputo 2× VM B2s | D39: 84.972 | E39: =D39*usd
A40: Microsoft Azure (Chile Central, Santiago) | B40: Alto | C40: BD PostgreSQL Flexible B2ms con alta disponibilidad | D40: 277.984 | E40: =D40*usd
A41: Microsoft Azure (Chile Central, Santiago) | B41: Alto | C41: Almacenamiento BD 128 GB (HA) | D41: 41.216 | E41: =D41*usd
...

Sheet Resumen_Cloud
A1: Resumen comparativo (CLP)
A3: Proveedor | B3: Bajo/mes | C3: Bajo/año | D3: Medio/mes | E3: Medio/año | F3: Alto/mes | G3: Alto/año
A4: AWS (sa-east-1 São Paulo) | B4: =Costos_Cloud!E10 | C4: =Costos_Cloud!E10*12 | D4: =Costos_Cloud!E17 | E4: =Costos_Cloud!E17*12 | F4: =Costos_Cloud!E24 | G4: =Costos_Cloud!E24*12
A5: Microsoft Azure (Chile Central, Santiago) | B5: =Costos_Cloud!E31 | C5: =Costos_Cloud!E31*12 | D5: =Costos_Cloud!E38 | E5: =Costos_Cloud!E38*12 | F5: =Costos_Cloud!E45 | G5: =Costos_Cloud!E45*12
A6: Google Cloud (southamerica-west1, Santiago) | B6: =Costos_Cloud!E52 | C6: =Costos_Cloud!E52*12 | D6: =Costos_Cloud!E59 | E6: =Costos_Cloud!E59*12 | F6: =Costos_Cloud!E66 | G6: =Costos_Cloud!E66*12
A7: VPS en Chile (V2Networks, Santiago) | B7: =Costos_Cloud!E68 | C7: =Costos_Cloud!E68*12 | D7: =Costos_Cloud!E71 | E7: =Costos_Cloud!E71*12 | F7: =Costos_Cloud!E74 | G7: =Costos_Cloud!E74*12

Sheet Referencias
A1: Referencias (APA 7.ª edición)
A3: Amazon Web Services [AWS]. (2026). AWS Price List: Amazon EC2, Amazon RDS for PostgreSQL y Amazon S3, región South America (São Paulo) [Conjunto de datos]. Recuperado el 6 de octubre de 2026, de https://b0.p.awsstatic.com/pricing/2.0/meteredUnitMaps/
A4: Amazon. (2025, 7 de mayo). Amazon to invest more than $4 billion to launch infrastructure region in Chile [Comunicado de prensa]. Business Wire. https://www.businesswire.com/news/home/20250507585471/en/
A5: Bytebase. (2026). Google Cloud SQL pricing: every machine type, Enterprise & Enterprise Plus. Recuperado el 6 de octubre de 2026, de https://www.bytebase.com/dbcost/cloudsql-pricing/
A6: Carey Abogados. (2026). Gobierno ingresa proyecto de ley que posterga en un año entrada en vigor de la Ley 21.719 sobre Protección de Datos Personales y fortalece la institucionalidad de la Agencia de Protección de Datos Personales. https://www.carey.cl/gobierno-ingresa-proyecto-de-ley-que-posterga-en-un-ano-entrada-en-vigor-de-la-ley-sobre-proteccion-de-datos-personales
A7: DAMA International. (2017). DAMA-DMBOK: Data management body of knowledge (2.ª ed.). Technics Publications.
A8: Digitalízame. (2026). Comisiones de Transbank, Mercado Pago y Flow en Chile (2026). https://digitalizame.cl/comisiones-pasarelas-de-pago-chile/
A9: gcloud-compute.com. (2026). e2-small: Google Compute Engine machine type pricing. Recuperado el 6 de octubre de 2026, de https://gcloud-compute.com/e2-small.html
A10: Google Cloud. (2026). Standard Support. Recuperado el 6 de octubre de 2026, de https://cloud.google.com/support/standard
A11: IEEE. (1998). IEEE recommended practice for software requirements specifications (IEEE Std 830-1998). https://doi.org/10.1109/IEEESTD.1998.88286
A12: Indeed. (2026). Sueldo de desarrollador/a junior en Chile. Recuperado el 6 de octubre de 2026, de https://cl.indeed.com/career/desarrollador-junior/salaries
A13: International Organization for Standardization & International Electrotechnical Commission [ISO/IEC]. (2011). Systems and software engineering — Systems and software Quality Requirements and Evaluation (SQuaRE) — System and software quality models (ISO/IEC 25010:2011).
... A32: World Wide Web Consortium [W3C]. (2018). Web Content Accessibility Guidelines (WCAG) 2.1. https://www.w3.org/TR/WCAG21/
